Not Found: /
"GET / HTTP/1.1" 404 179
Not Found: /favicon.ico
"GET /favicon.ico HTTP/1.1" 404 179
Not Found: /
"GET / HTTP/1.1" 404 2480
Not Found: /
"GET / HTTP/1.1" 404 179
Not Found: /favicon.ico
"GET /favicon.ico HTTP/1.1" 404 179
Not Found: /static/drf-yasg/swagger-ui-dist/swagger-ui.css
Not Found: /static/drf-yasg/swagger-ui-dist/swagger-ui-bundle.js
"GET /static/drf-yasg/swagger-ui-dist/swagger-ui.css HTTP/1.1" 404 179
Not Found: /static/drf-yasg/swagger-ui-dist/swagger-ui-standalone-preset.js
"GET /static/drf-yasg/swagger-ui-dist/swagger-ui-bundle.js HTTP/1.1" 404 179
Not Found: /static/drf-yasg/swagger-ui-init.js
"GET /static/drf-yasg/swagger-ui-dist/swagger-ui-standalone-preset.js HTTP/1.1" 404 179
Not Found: /static/drf-yasg/style.css
Not Found: /static/drf-yasg/insQ.min.js
"GET /static/drf-yasg/swagger-ui-init.js HTTP/1.1" 404 179
Not Found: /static/drf-yasg/immutable.min.js
"GET /static/drf-yasg/style.css HTTP/1.1" 404 179
"GET /static/drf-yasg/insQ.min.js HTTP/1.1" 404 179
"GET /static/drf-yasg/immutable.min.js HTTP/1.1" 404 179
Not Found: /accounts/login/
"GET /accounts/login/?next=/docs/ HTTP/1.1" 404 179
Not Found: /accounts/login/
"GET /accounts/login/?next=/docs/ HTTP/1.1" 404 2555
Not Found: /static/drf-yasg/style.css
Not Found: /static/drf-yasg/swagger-ui-dist/swagger-ui.css
"GET /static/drf-yasg/style.css HTTP/1.1" 404 179
"GET /static/drf-yasg/swagger-ui-dist/swagger-ui.css HTTP/1.1" 404 179
Not Found: /static/drf-yasg/swagger-ui-init.js
"GET /static/drf-yasg/swagger-ui-init.js HTTP/1.1" 404 179
Not Found: /static/drf-yasg/swagger-ui-dist/swagger-ui-bundle.js
"GET /static/drf-yasg/swagger-ui-dist/swagger-ui-bundle.js HTTP/1.1" 404 179
Not Found: /static/drf-yasg/swagger-ui-dist/swagger-ui-standalone-preset.js
Not Found: /static/drf-yasg/insQ.min.js
"GET /static/drf-yasg/swagger-ui-dist/swagger-ui-standalone-preset.js HTTP/1.1" 404 179
"GET /static/drf-yasg/insQ.min.js HTTP/1.1" 404 179
Not Found: /static/drf-yasg/immutable.min.js
"GET /static/drf-yasg/immutable.min.js HTTP/1.1" 404 179
Not Found: /accounts/login/
"GET /accounts/login/?next=/docs/ HTTP/1.1" 404 179
Not Found: /static/drf-yasg/style.css
Not Found: /static/drf-yasg/swagger-ui-dist/swagger-ui.css
Not Found: /static/drf-yasg/swagger-ui-dist/swagger-ui-bundle.js
"GET /static/drf-yasg/style.css HTTP/1.1" 404 179
"GET /static/drf-yasg/swagger-ui-dist/swagger-ui.css HTTP/1.1" 404 179
Not Found: /static/drf-yasg/swagger-ui-dist/swagger-ui-standalone-preset.js
"GET /static/drf-yasg/swagger-ui-dist/swagger-ui-bundle.js HTTP/1.1" 404 179
Not Found: /static/drf-yasg/swagger-ui-init.js
"GET /static/drf-yasg/swagger-ui-dist/swagger-ui-standalone-preset.js HTTP/1.1" 404 179
"GET /static/drf-yasg/swagger-ui-init.js HTTP/1.1" 404 179
Not Found: /static/drf-yasg/insQ.min.js
"GET /static/drf-yasg/insQ.min.js HTTP/1.1" 404 179
Not Found: /static/drf-yasg/immutable.min.js
"GET /static/drf-yasg/immutable.min.js HTTP/1.1" 404 179
Not Found: /api/docs
"GET /api/docs HTTP/1.1" 404 179
Not Found: /api/docs/
"GET /api/docs/ HTTP/1.1" 404 179
Internal Server Error: /api/strings
Traceback (most recent call last):
  File "C:\Users\HP\Desktop\string_analyzer\venv\Lib\site-packages\django\db\backends\utils.py", line 105, in _execute
    return self.cursor.execute(sql, params)
           ~~~~~~~~~~~~~~~~~~~^^^^^^^^^^^^^
  File "C:\Users\HP\Desktop\string_analyzer\venv\Lib\site-packages\django\db\backends\sqlite3\base.py", line 360, in execute
    return super().execute(query, params)
           ~~~~~~~~~~~~~~~^^^^^^^^^^^^^^^
sqlite3.OperationalError: no such table: analyzer_stringrecord

The above exception was the direct cause of the following exception:

Traceback (most recent call last):
  File "C:\Users\HP\Desktop\string_analyzer\venv\Lib\site-packages\django\core\handlers\exception.py", line 55, in inner
    response = get_response(request)
  File "C:\Users\HP\Desktop\string_analyzer\venv\Lib\site-packages\django\core\handlers\base.py", line 197, in _get_response
    response = wrapped_callback(request, *callback_args, **callback_kwargs)
  File "C:\Users\HP\Desktop\string_analyzer\venv\Lib\site-packages\django\views\decorators\csrf.py", line 65, in _view_wrapper
    return view_func(request, *args, **kwargs)
  File "C:\Users\HP\Desktop\string_analyzer\venv\Lib\site-packages\django\views\generic\base.py", line 105, in view
    return self.dispatch(request, *args, **kwargs)
           ~~~~~~~~~~~~~^^^^^^^^^^^^^^^^^^^^^^^^^^
  File "C:\Users\HP\Desktop\string_analyzer\venv\Lib\site-packages\rest_framework\views.py", line 515, in dispatch
    response = self.handle_exception(exc)
  File "C:\Users\HP\Desktop\string_analyzer\venv\Lib\site-packages\rest_framework\views.py", line 475, in handle_exception
    self.raise_uncaught_exception(exc)
    ~~~~~~~~~~~~~~~~~~~~~~~~~~~~~^^^^^
  File "C:\Users\HP\Desktop\string_analyzer\venv\Lib\site-packages\rest_framework\views.py", line 486, in raise_uncaught_exception
    raise exc
  File "C:\Users\HP\Desktop\string_analyzer\venv\Lib\site-packages\rest_framework\views.py", line 512, in dispatch
    response = handler(request, *args, **kwargs)
  File "C:\Users\HP\Desktop\string_analyzer\venv\Lib\site-packages\rest_framework\generics.py", line 243, in get
    return self.list(request, *args, **kwargs)
           ~~~~~~~~~^^^^^^^^^^^^^^^^^^^^^^^^^^
  File "C:\Users\HP\Desktop\string_analyzer\venv\Lib\site-packages\rest_framework\mixins.py", line 46, in list
    return Response(serializer.data)
                    ^^^^^^^^^^^^^^^
  File "C:\Users\HP\Desktop\string_analyzer\venv\Lib\site-packages\rest_framework\serializers.py", line 797, in data
    ret = super().data
          ^^^^^^^^^^^^
  File "C:\Users\HP\Desktop\string_analyzer\venv\Lib\site-packages\rest_framework\serializers.py", line 251, in data
    self._data = self.to_representation(self.instance)
                 ~~~~~~~~~~~~~~~~~~~~~~^^^^^^^^^^^^^^^
  File "C:\Users\HP\Desktop\string_analyzer\venv\Lib\site-packages\rest_framework\serializers.py", line 716, in to_representation
    self.child.to_representation(item) for item in iterable
                                                   ^^^^^^^^
  File "C:\Users\HP\Desktop\string_analyzer\venv\Lib\site-packages\django\db\models\query.py", line 384, in __iter__
    self._fetch_all()
    ~~~~~~~~~~~~~~~^^
  File "C:\Users\HP\Desktop\string_analyzer\venv\Lib\site-packages\django\db\models\query.py", line 1949, in _fetch_all
    self._result_cache = list(self._iterable_class(self))
                         ~~~~^^^^^^^^^^^^^^^^^^^^^^^^^^^^
  File "C:\Users\HP\Desktop\string_analyzer\venv\Lib\site-packages\django\db\models\query.py", line 91, in __iter__
    results = compiler.execute_sql(
        chunked_fetch=self.chunked_fetch, chunk_size=self.chunk_size
    )
  File "C:\Users\HP\Desktop\string_analyzer\venv\Lib\site-packages\django\db\models\sql\compiler.py", line 1623, in execute_sql
    cursor.execute(sql, params)
    ~~~~~~~~~~~~~~^^^^^^^^^^^^^
  File "C:\Users\HP\Desktop\string_analyzer\venv\Lib\site-packages\django\db\backends\utils.py", line 79, in execute
    return self._execute_with_wrappers(
           ~~~~~~~~~~~~~~~~~~~~~~~~~~~^
        sql, params, many=False, executor=self._execute
        ^^^^^^^^^^^^^^^^^^^^^^^^^^^^^^^^^^^^^^^^^^^^^^^
    )
    ^
  File "C:\Users\HP\Desktop\string_analyzer\venv\Lib\site-packages\django\db\backends\utils.py", line 92, in _execute_with_wrappers
    return executor(sql, params, many, context)
  File "C:\Users\HP\Desktop\string_analyzer\venv\Lib\site-packages\django\db\backends\utils.py", line 100, in _execute
    with self.db.wrap_database_errors:
         ^^^^^^^^^^^^^^^^^^^^^^^^^^^^
  File "C:\Users\HP\Desktop\string_analyzer\venv\Lib\site-packages\django\db\utils.py", line 91, in __exit__
    raise dj_exc_value.with_traceback(traceback) from exc_value
  File "C:\Users\HP\Desktop\string_analyzer\venv\Lib\site-packages\django\db\backends\utils.py", line 105, in _execute
    return self.cursor.execute(sql, params)
           ~~~~~~~~~~~~~~~~~~~^^^^^^^^^^^^^
  File "C:\Users\HP\Desktop\string_analyzer\venv\Lib\site-packages\django\db\backends\sqlite3\base.py", line 360, in execute
    return super().execute(query, params)
           ~~~~~~~~~~~~~~~^^^^^^^^^^^^^^^
django.db.utils.OperationalError: no such table: analyzer_stringrecord
"GET /api/strings HTTP/1.1" 500 145
Internal Server Error: /api/strings
Traceback (most recent call last):
  File "C:\Users\HP\Desktop\string_analyzer\venv\Lib\site-packages\django\db\backends\utils.py", line 105, in _execute
    return self.cursor.execute(sql, params)
           ~~~~~~~~~~~~~~~~~~~^^^^^^^^^^^^^
  File "C:\Users\HP\Desktop\string_analyzer\venv\Lib\site-packages\django\db\backends\sqlite3\base.py", line 360, in execute
    return super().execute(query, params)
           ~~~~~~~~~~~~~~~^^^^^^^^^^^^^^^
sqlite3.OperationalError: no such table: analyzer_stringrecord

The above exception was the direct cause of the following exception:

Traceback (most recent call last):
  File "C:\Users\HP\Desktop\string_analyzer\venv\Lib\site-packages\django\core\handlers\exception.py", line 55, in inner
    response = get_response(request)
  File "C:\Users\HP\Desktop\string_analyzer\venv\Lib\site-packages\django\core\handlers\base.py", line 197, in _get_response
    response = wrapped_callback(request, *callback_args, **callback_kwargs)
  File "C:\Users\HP\Desktop\string_analyzer\venv\Lib\site-packages\django\views\decorators\csrf.py", line 65, in _view_wrapper
    return view_func(request, *args, **kwargs)
  File "C:\Users\HP\Desktop\string_analyzer\venv\Lib\site-packages\django\views\generic\base.py", line 105, in view
    return self.dispatch(request, *args, **kwargs)
           ~~~~~~~~~~~~~^^^^^^^^^^^^^^^^^^^^^^^^^^
  File "C:\Users\HP\Desktop\string_analyzer\venv\Lib\site-packages\rest_framework\views.py", line 515, in dispatch
    response = self.handle_exception(exc)
  File "C:\Users\HP\Desktop\string_analyzer\venv\Lib\site-packages\rest_framework\views.py", line 475, in handle_exception
    self.raise_uncaught_exception(exc)
    ~~~~~~~~~~~~~~~~~~~~~~~~~~~~~^^^^^
  File "C:\Users\HP\Desktop\string_analyzer\venv\Lib\site-packages\rest_framework\views.py", line 486, in raise_uncaught_exception
    raise exc
  File "C:\Users\HP\Desktop\string_analyzer\venv\Lib\site-packages\rest_framework\views.py", line 512, in dispatch
    response = handler(request, *args, **kwargs)
  File "C:\Users\HP\Desktop\string_analyzer\venv\Lib\site-packages\rest_framework\generics.py", line 243, in get
    return self.list(request, *args, **kwargs)
           ~~~~~~~~~^^^^^^^^^^^^^^^^^^^^^^^^^^
  File "C:\Users\HP\Desktop\string_analyzer\venv\Lib\site-packages\rest_framework\mixins.py", line 46, in list
    return Response(serializer.data)
                    ^^^^^^^^^^^^^^^
  File "C:\Users\HP\Desktop\string_analyzer\venv\Lib\site-packages\rest_framework\serializers.py", line 797, in data
    ret = super().data
          ^^^^^^^^^^^^
  File "C:\Users\HP\Desktop\string_analyzer\venv\Lib\site-packages\rest_framework\serializers.py", line 251, in data
    self._data = self.to_representation(self.instance)
                 ~~~~~~~~~~~~~~~~~~~~~~^^^^^^^^^^^^^^^
  File "C:\Users\HP\Desktop\string_analyzer\venv\Lib\site-packages\rest_framework\serializers.py", line 716, in to_representation
    self.child.to_representation(item) for item in iterable
                                                   ^^^^^^^^
  File "C:\Users\HP\Desktop\string_analyzer\venv\Lib\site-packages\django\db\models\query.py", line 384, in __iter__
    self._fetch_all()
    ~~~~~~~~~~~~~~~^^
  File "C:\Users\HP\Desktop\string_analyzer\venv\Lib\site-packages\django\db\models\query.py", line 1949, in _fetch_all
    self._result_cache = list(self._iterable_class(self))
                         ~~~~^^^^^^^^^^^^^^^^^^^^^^^^^^^^
  File "C:\Users\HP\Desktop\string_analyzer\venv\Lib\site-packages\django\db\models\query.py", line 91, in __iter__
    results = compiler.execute_sql(
        chunked_fetch=self.chunked_fetch, chunk_size=self.chunk_size
    )
  File "C:\Users\HP\Desktop\string_analyzer\venv\Lib\site-packages\django\db\models\sql\compiler.py", line 1623, in execute_sql
    cursor.execute(sql, params)
    ~~~~~~~~~~~~~~^^^^^^^^^^^^^
  File "C:\Users\HP\Desktop\string_analyzer\venv\Lib\site-packages\django\db\backends\utils.py", line 79, in execute
    return self._execute_with_wrappers(
           ~~~~~~~~~~~~~~~~~~~~~~~~~~~^
        sql, params, many=False, executor=self._execute
        ^^^^^^^^^^^^^^^^^^^^^^^^^^^^^^^^^^^^^^^^^^^^^^^
    )
    ^
  File "C:\Users\HP\Desktop\string_analyzer\venv\Lib\site-packages\django\db\backends\utils.py", line 92, in _execute_with_wrappers
    return executor(sql, params, many, context)
  File "C:\Users\HP\Desktop\string_analyzer\venv\Lib\site-packages\django\db\backends\utils.py", line 100, in _execute
    with self.db.wrap_database_errors:
         ^^^^^^^^^^^^^^^^^^^^^^^^^^^^
  File "C:\Users\HP\Desktop\string_analyzer\venv\Lib\site-packages\django\db\utils.py", line 91, in __exit__
    raise dj_exc_value.with_traceback(traceback) from exc_value
  File "C:\Users\HP\Desktop\string_analyzer\venv\Lib\site-packages\django\db\backends\utils.py", line 105, in _execute
    return self.cursor.execute(sql, params)
           ~~~~~~~~~~~~~~~~~~~^^^^^^^^^^^^^
  File "C:\Users\HP\Desktop\string_analyzer\venv\Lib\site-packages\django\db\backends\sqlite3\base.py", line 360, in execute
    return super().execute(query, params)
           ~~~~~~~~~~~~~~~^^^^^^^^^^^^^^^
django.db.utils.OperationalError: no such table: analyzer_stringrecord
"GET /api/strings HTTP/1.1" 500 145
Internal Server Error: /api/strings
Traceback (most recent call last):
  File "C:\Users\HP\Desktop\string_analyzer\venv\Lib\site-packages\django\db\backends\utils.py", line 105, in _execute
    return self.cursor.execute(sql, params)
           ~~~~~~~~~~~~~~~~~~~^^^^^^^^^^^^^
  File "C:\Users\HP\Desktop\string_analyzer\venv\Lib\site-packages\django\db\backends\sqlite3\base.py", line 360, in execute
    return super().execute(query, params)
           ~~~~~~~~~~~~~~~^^^^^^^^^^^^^^^
sqlite3.OperationalError: no such table: analyzer_stringrecord

The above exception was the direct cause of the following exception:

Traceback (most recent call last):
  File "C:\Users\HP\Desktop\string_analyzer\venv\Lib\site-packages\django\core\handlers\exception.py", line 55, in inner
    response = get_response(request)
  File "C:\Users\HP\Desktop\string_analyzer\venv\Lib\site-packages\django\core\handlers\base.py", line 197, in _get_response
    response = wrapped_callback(request, *callback_args, **callback_kwargs)
  File "C:\Users\HP\Desktop\string_analyzer\venv\Lib\site-packages\django\views\decorators\csrf.py", line 65, in _view_wrapper
    return view_func(request, *args, **kwargs)
  File "C:\Users\HP\Desktop\string_analyzer\venv\Lib\site-packages\django\views\generic\base.py", line 105, in view
    return self.dispatch(request, *args, **kwargs)
           ~~~~~~~~~~~~~^^^^^^^^^^^^^^^^^^^^^^^^^^
  File "C:\Users\HP\Desktop\string_analyzer\venv\Lib\site-packages\rest_framework\views.py", line 515, in dispatch
    response = self.handle_exception(exc)
  File "C:\Users\HP\Desktop\string_analyzer\venv\Lib\site-packages\rest_framework\views.py", line 475, in handle_exception
    self.raise_uncaught_exception(exc)
    ~~~~~~~~~~~~~~~~~~~~~~~~~~~~~^^^^^
  File "C:\Users\HP\Desktop\string_analyzer\venv\Lib\site-packages\rest_framework\views.py", line 486, in raise_uncaught_exception
    raise exc
  File "C:\Users\HP\Desktop\string_analyzer\venv\Lib\site-packages\rest_framework\views.py", line 512, in dispatch
    response = handler(request, *args, **kwargs)
  File "C:\Users\HP\Desktop\string_analyzer\venv\Lib\site-packages\rest_framework\generics.py", line 243, in get
    return self.list(request, *args, **kwargs)
           ~~~~~~~~~^^^^^^^^^^^^^^^^^^^^^^^^^^
  File "C:\Users\HP\Desktop\string_analyzer\venv\Lib\site-packages\rest_framework\mixins.py", line 46, in list
    return Response(serializer.data)
                    ^^^^^^^^^^^^^^^
  File "C:\Users\HP\Desktop\string_analyzer\venv\Lib\site-packages\rest_framework\serializers.py", line 797, in data
    ret = super().data
          ^^^^^^^^^^^^
  File "C:\Users\HP\Desktop\string_analyzer\venv\Lib\site-packages\rest_framework\serializers.py", line 251, in data
    self._data = self.to_representation(self.instance)
                 ~~~~~~~~~~~~~~~~~~~~~~^^^^^^^^^^^^^^^
  File "C:\Users\HP\Desktop\string_analyzer\venv\Lib\site-packages\rest_framework\serializers.py", line 716, in to_representation
    self.child.to_representation(item) for item in iterable
                                                   ^^^^^^^^
  File "C:\Users\HP\Desktop\string_analyzer\venv\Lib\site-packages\django\db\models\query.py", line 384, in __iter__
    self._fetch_all()
    ~~~~~~~~~~~~~~~^^
  File "C:\Users\HP\Desktop\string_analyzer\venv\Lib\site-packages\django\db\models\query.py", line 1949, in _fetch_all
    self._result_cache = list(self._iterable_class(self))
                         ~~~~^^^^^^^^^^^^^^^^^^^^^^^^^^^^
  File "C:\Users\HP\Desktop\string_analyzer\venv\Lib\site-packages\django\db\models\query.py", line 91, in __iter__
    results = compiler.execute_sql(
        chunked_fetch=self.chunked_fetch, chunk_size=self.chunk_size
    )
  File "C:\Users\HP\Desktop\string_analyzer\venv\Lib\site-packages\django\db\models\sql\compiler.py", line 1623, in execute_sql
    cursor.execute(sql, params)
    ~~~~~~~~~~~~~~^^^^^^^^^^^^^
  File "C:\Users\HP\Desktop\string_analyzer\venv\Lib\site-packages\django\db\backends\utils.py", line 79, in execute
    return self._execute_with_wrappers(
           ~~~~~~~~~~~~~~~~~~~~~~~~~~~^
        sql, params, many=False, executor=self._execute
        ^^^^^^^^^^^^^^^^^^^^^^^^^^^^^^^^^^^^^^^^^^^^^^^
    )
    ^
  File "C:\Users\HP\Desktop\string_analyzer\venv\Lib\site-packages\django\db\backends\utils.py", line 92, in _execute_with_wrappers
    return executor(sql, params, many, context)
  File "C:\Users\HP\Desktop\string_analyzer\venv\Lib\site-packages\django\db\backends\utils.py", line 100, in _execute
    with self.db.wrap_database_errors:
         ^^^^^^^^^^^^^^^^^^^^^^^^^^^^
  File "C:\Users\HP\Desktop\string_analyzer\venv\Lib\site-packages\django\db\utils.py", line 91, in __exit__
    raise dj_exc_value.with_traceback(traceback) from exc_value
  File "C:\Users\HP\Desktop\string_analyzer\venv\Lib\site-packages\django\db\backends\utils.py", line 105, in _execute
    return self.cursor.execute(sql, params)
           ~~~~~~~~~~~~~~~~~~~^^^^^^^^^^^^^
  File "C:\Users\HP\Desktop\string_analyzer\venv\Lib\site-packages\django\db\backends\sqlite3\base.py", line 360, in execute
    return super().execute(query, params)
           ~~~~~~~~~~~~~~~^^^^^^^^^^^^^^^
django.db.utils.OperationalError: no such table: analyzer_stringrecord
"GET /api/strings HTTP/1.1" 500 145
Not Found: /api/
"GET /api/ HTTP/1.1" 404 179
Not Found: /string-form/
"GET /string-form/ HTTP/1.1" 404 2677
Not Found: /favicon.ico
"GET /favicon.ico HTTP/1.1" 404 2674
Not Found: /favicon.ico
"GET /favicon.ico HTTP/1.1" 404 2674
Bad Request: /api/strings/filter-by-natural-language
"GET /api/strings/filter-by-natural-language HTTP/1.1" 400 29
Not Found: /favicon.ico
"GET /favicon.ico HTTP/1.1" 404 3393
